Workbook

Sheet Dashboard
A2: Lifelong learning income dashboard
A3: UK comparable CPD/CE income | 2024/25 | HESA HE-BCI provider returns
A5: UK income (£m) | F5: HE providers | K5: Learner days | Q5: Top provider | R5: CPD/CE (£m)
A6: =SUM('UK providers'!I7:I212)/1000 | F6: =COUNTA('UK providers'!A7:A212) | K6: =SUM('UK providers'!J7:J212) | Q6: =INDEX('UK providers'!$Q$7:$Q$212,MATCH(1,'UK providers'!$P$7:$P$212,0)) | R6: =INDEX('UK providers'!$K$7:$K$212,MATCH(1,'UK providers'!$P$7:$P$212,0))
Q7: =INDEX('UK providers'!$Q$7:$Q$212,MATCH(2,'UK providers'!$P$7:$P$212,0)) | R7: =INDEX('UK providers'!$K$7:$K$212,MATCH(2,'UK providers'!$P$7:$P$212,0))
Q8: =INDEX('UK providers'!$Q$7:$Q$212,MATCH(3,'UK providers'!$P$7:$P$212,0)) | R8: =INDEX('UK providers'!$K$7:$K$212,MATCH(3,'UK providers'!$P$7:$P$212,0))
A9: CPD/CE is a defined part of lifelong learning. These HE providers extend beyond universities. The supplied file contains one year, so a UK HESA income growth trend is unavailable. | Q9: =INDEX('UK providers'!$Q$7:$Q$212,MATCH(4,'UK providers'!$P$7:$P$212,0)) | R9: =INDEX('UK providers'!$K$7:$K$212,MATCH(4,'UK providers'!$P$7:$P$212,0))
Q10: =INDEX('UK providers'!$Q$7:$Q$212,MATCH(5,'UK providers'!$P$7:$P$212,0)) | R10: =INDEX('UK providers'!$K$7:$K$212,MATCH(5,'UK providers'!$P$7:$P$212,0))
Q11: =INDEX('UK providers'!$Q$7:$Q$212,MATCH(6,'UK providers'!$P$7:$P$212,0)) | R11: =INDEX('UK providers'!$K$7:$K$212,MATCH(6,'UK providers'!$P$7:$P$212,0))
A12: UK income by research cohort | I12: Customer mix | Q12: =INDEX('UK providers'!$Q$7:$Q$212,MATCH(7,'UK providers'!$P$7:$P$212,0)) | R12: =INDEX('UK providers'!$K$7:$K$212,MATCH(7,'UK providers'!$P$7:$P$212,0))
Q13: =INDEX('UK providers'!$Q$7:$Q$212,MATCH(8,'UK providers'!$P$7:$P$212,0)) | R13: =INDEX('UK providers'!$K$7:$K$212,MATCH(8,'UK providers'!$P$7:$P$212,0))
A14: Cohort | D14: Providers | F14: Income (£m) | I14: Customer | M14: Income (£m) | Q14: =INDEX('UK providers'!$Q$7:$Q$212,MATCH(9,'UK providers'!$P$7:$P$212,0)) | R14: =INDEX('UK providers'!$K$7:$K$212,MATCH(9,'UK providers'!$P$7:$P$212,0))
A15: Russell Group | D15: =COUNTIF('UK providers'!$C$7:$C$212,A15) | F15: =SUMIF('UK providers'!$C$7:$C$212,A15,'UK providers'!$K$7:$K$212) | I15: Individuals | M15: =SUM('UK providers'!H7:H212)/1000 | Q15: =INDEX('UK providers'!$Q$7:$Q$212,MATCH(10,'UK providers'!$P$7:$P$212,0)) | R15: =INDEX('UK providers'!$K$7:$K$212,MATCH(10,'UK providers'!$P$7:$P$212,0))
A16: Additional UK sample | D16: =COUNTIF('UK providers'!$C$7:$C$212,A16) | F16: =SUMIF('UK providers'!$C$7:$C$212,A16,'UK providers'!$K$7:$K$212) | I16: Non-commercial | M16: =SUM('UK providers'!G7:G212)/1000
A17: Other HE provider | D17: =COUNTIF('UK providers'!$C$7:$C$212,A17) | F17: =SUMIF('UK providers'!$C$7:$C$212,A17,'UK providers'!$K$7:$K$212) | I17: Other commercial | M17: =SUM('UK providers'!F7:F212)/1000
I18: SMEs | M18: =SUM('UK providers'!E7:E212)/1000 | Q18: Customer | R18: CPD/CE (£m)
A19: Share from individual learners | F19: =SUM('UK providers'!H7:H212)/SUM('UK providers'!I7:I212) | Q19: =I15 | R19: =M15
Q20: =I16 | R20: =M16
Q21: =I17 | R21: =M17
Q22: =I18 | R22: =M18
A42: Australian revenue and growth: seven of the top 10 institutions
A43: Separate measures in AUD millions. Melbourne is the Business School entity. Periods and definitions differ; amounts must not be aggregated. Three institutions have no comparable numeric row.
A46: Institution | D46: Reported metric | I46: Current period | K46: AUD m | M46: Growth
A47: ='Revenue evidence'!B32 | D47: ='Revenue evidence'!D32 | I47: ='Revenue evidence'!H32 | K47: ='Revenue evidence'!I32 | M47: ='Revenue evidence'!J32
A48: ='Revenue evidence'!B33 | D48: ='Revenue evidence'!D33 | I48: ='Revenue evidence'!H33 | K48: ='Revenue evidence'!I33 | M48: ='Revenue evidence'!J33
A49: ='Revenue evidence'!B34 | D49: ='Revenue evidence'!D34 | I49: ='Revenue evidence'!H34 | K49: ='Revenue evidence'!I34 | M49: ='Revenue evidence'!J34
A50: ='Revenue evidence'!B37 | D50: ='Revenue evidence'!D37 | I50: ='Revenue evidence'!H37 | K50: ='Revenue evidence'!I37 | M50: ='Revenue evidence'!J37
A51: ='Revenue evidence'!B38 | D51: ='Revenue evidence'!D38 | I51: ='Revenue evidence'!H38 | K51: ='Revenue evidence'!I38 | M51: ='Revenue evidence'!J38
A52: ='Revenue evidence'!B40 | D52: ='Revenue evidence'!D40 | I52: ='Revenue evidence'!H40 | K52: ='Revenue evidence'!I40 | M52: ='Revenue evidence'!J40
A53: ='Revenue evidence'!B41 | D53: ='Revenue evidence'!D41 | I53: ='Revenue evidence'!H41 | K53: ='Revenue evidence'!I41 | M53: ='Revenue evidence'!J41
A56: Experiential-learning research coverage (strict-definition review; detail in 'EL dashboard')
A57: Institutions in scope / reviewed | F57: =COUNTA('EL institution summary'!$A$7:$A$130) | I57: Current qualifying schemes | M57: =COUNTIF('EL scheme register'!$AJ$7:$AJ$610,"Yes")
A58: With ≥1 current qualifying scheme | F58: =COUNTIF('EL institution summary'!$N$7:$N$130,">0") | I58: Institutions fully reviewed | M58: =COUNTIF('EL institution summary'!$H$7:$H$130,"Complete")
A60: Qualifying = project-based, group working and connected to a real external organisation on the same route, with current delivery confirmed. The legacy scheme sample (152 frameworks/examples) is retained in 'Legacy schemes (v3)'. Lifelong-learning revenue above is NOT revenue from these schemes.

Sheet EL dashboard
A2: Experiential learning dashboard: collaborative employer-connected projects
A3: Findings within the researched 124-institution sample (purposive, not random) — not estimates of national prevalence. A qualifying scheme = project-based AND group working AND connected to a real external organisation (all Yes on the same route) with current delivery confirmed; umbrellas with counted children are not double-counted.
A6: Institutions in scope | C6: Fully reviewed | E6: Partially reviewed | H6: Not yet reviewed | J6: With ≥1 current qualifying scheme
A7: =COUNTA('EL institution summary'!$A$7:$A$130) | C7: =COUNTIF('EL institution summary'!$H$7:$H$130,"Complete") | E7: =COUNTIF('EL institution summary'!$H$7:$H$130,"Partial") | H7: =COUNTIF('EL institution summary'!$H$7:$H$130,"Not started") | J7: =COUNTIF('EL institution summary'!$N$7:$N$130,">0")
J8: denominator = reviewed (full + partial)
A10: Distinct current qualifying schemes | C10: Records in scheme register | E10: Exclusion / near-miss records | H10: Source rows (claim-level) | J10: Reviewed institutions with none verified
A11: =COUNTIF('EL scheme register'!$AJ$7:$AJ$610,"Yes") | C11: =COUNTA('EL scheme register'!$D$7:$D$610) | E11: =COUNTA('EL exclusions & gaps'!$A$7:$A$5000) | H11: =COUNTA('EL sources'!$A$7:$A$20000) | J11: =COUNTIFS('EL institution summary'!$H$7:$H$130,"<>Not started",'EL institution summary'!$N$7:$N$130,0)
J12: "no qualifying scheme verified through the documented search"
A15: Current qualifying schemes by academic reach | H15: Breakdown by country / region group
A16: Academic reach | B16: Schemes | C16: Institutions with ≥1 | D16: Share of qualifying schemes | H16: Region group | I16: In scope | J16: Reviewed (full+partial) | K16: With ≥1 qualifying | L16: Qualifying schemes | M16: University-wide qualifying
A17: University-wide | B17: =COUNTIFS('EL scheme register'!$C$7:$C$610,A17,'EL scheme register'!$AJ$7:$AJ$610,"Yes") | C17: =COUNTIF('EL institution summary'!$I$7:$I$130,">0") | D17: =IF(SUM($B$17:$B$21)=0,"n/a",B17/SUM($B$17:$B$21)) | H17: UK – Russell Group | I17: =COUNTIF('EL institution summary'!$E$7:$E$130,H17) | J17: =COUNTIFS('EL institution summary'!$E$7:$E$130,H17,'EL institution summary'!$H$7:$H$130,"<>Not started") | K17: =COUNTIFS('EL institution summary'!$E$7:$E$130,H17,'EL institution summary'!$N$7:$N$130,">0") | L17: =COUNTIFS('EL scheme register'!$AP$7:$AP$610,H17,'EL scheme register'!$AJ$7:$AJ$610,"Yes") | M17: =COUNTIFS('EL scheme register'!$AP$7:$AP$610,H17,'EL scheme register'!$AJ$7:$AJ$610,"Yes",'EL scheme register'!$C$7:$C$610,"University-wide")
A18: Cross-faculty | B18: =COUNTIFS('EL scheme register'!$C$7:$C$610,A18,'EL scheme register'!$AJ$7:$AJ$610,"Yes") | C18: =COUNTIF('EL institution summary'!$J$7:$J$130,">0") | D18: =IF(SUM($B$17:$B$21)=0,"n/a",B18/SUM($B$17:$B$21)) | H18: UK – additional | I18: =COUNTIF('EL institution summary'!$E$7:$E$130,H18) | J18: =COUNTIFS('EL institution summary'!$E$7:$E$130,H18,'EL institution summary'!$H$7:$H$130,"<>Not started") | K18: =COUNTIFS('EL institution summary'!$E$7:$E$130,H18,'EL institution summary'!$N$7:$N$130,">0") | L18: =COUNTIFS('EL scheme register'!$AP$7:$AP$610,H18,'EL scheme register'!$AJ$7:$AJ$610,"Yes") | M18: =COUNTIFS('EL scheme register'!$AP$7:$AP$610,H18,'EL scheme register'!$AJ$7:$AJ$610,"Yes",'EL scheme register'!$C$7:$C$610,"University-wide")
A19: Faculty/school | B19: =COUNTIFS('EL scheme register'!$C$7:$C$610,A19,'EL scheme register'!$AJ$7:$AJ$610,"Yes") | C19: =COUNTIF('EL institution summary'!$K$7:$K$130,">0") | D19: =IF(SUM($B$17:$B$21)=0,"n/a",B19/SUM($B$17:$B$21)) | H19: Australia | I19: =COUNTIF('EL institution summary'!$E$7:$E$130,H19) | J19: =COUNTIFS('EL institution summary'!$E$7:$E$130,H19,'EL institution summary'!$H$7:$H$130,"<>Not started") | K19: =COUNTIFS('EL institution summary'!$E$7:$E$130,H19,'EL institution summary'!$N$7:$N$130,">0") | L19: =COUNTIFS('EL scheme register'!$AP$7:$AP$610,H19,'EL scheme register'!$AJ$7:$AJ$610,"Yes") | M19: =COUNTIFS('EL scheme register'!$AP$7:$AP$610,H19,'EL scheme register'!$AJ$7:$AJ$610,"Yes",'EL scheme register'!$C$7:$C$610,"University-wide")
A20: Programme/course | B20: =COUNTIFS('EL scheme register'!$C$7:$C$610,A20,'EL scheme register'!$AJ$7:$AJ$610,"Yes") | C20: =COUNTIF('EL institution summary'!$L$7:$L$130,">0") | D20: =IF(SUM($B$17:$B$21)=0,"n/a",B20/SUM($B$17:$B$21)) | H20: US | I20: =COUNTIF('EL institution summary'!$E$7:$E$130,H20) | J20: =COUNTIFS('EL institution summary'!$E$7:$E$130,H20,'EL institution summary'!$H$7:$H$130,"<>Not started") | K20: =COUNTIFS('EL institution summary'!$E$7:$E$130,H20,'EL institution summary'!$N$7:$N$130,">0") | L20: =COUNTIFS('EL scheme register'!$AP$7:$AP$610,H20,'EL scheme register'!$AJ$7:$AJ$610,"Yes") | M20: =COUNTIFS('EL scheme register'!$AP$7:$AP$610,H20,'EL scheme register'!$AJ$7:$AJ$610,"Yes",'EL scheme register'!$C$7:$C$610,"University-wide")
A21: Unclear | B21: =COUNTIFS('EL scheme register'!$C$7:$C$610,A21,'EL scheme register'!$AJ$7:$AJ$610,"Yes") | C21: =COUNTIF('EL institution summary'!$M$7:$M$130,">0") | D21: =IF(SUM($B$17:$B$21)=0,"n/a",B21/SUM($B$17:$B$21)) | H21: EU | I21: =COUNTIF('EL institution summary'!$E$7:$E$130,H21) | J21: =COUNTIFS('EL institution summary'!$E$7:$E$130,H21,'EL institution summary'!$H$7:$H$130,"<>Not started") | K21: =COUNTIFS('EL institution summary'!$E$7:$E$130,H21,'EL institution summary'!$N$7:$N$130,">0") | L21: =COUNTIFS('EL scheme register'!$AP$7:$AP$610,H21,'EL scheme register'!$AJ$7:$AJ$610,"Yes") | M21: =COUNTIFS('EL scheme register'!$AP$7:$AP$610,H21,'EL scheme register'!$AJ$7:$AJ$610,"Yes",'EL scheme register'!$C$7:$C$610,"University-wide")
A22: Total | B22: =SUM(B17:B21) | C22: =COUNTIF('EL institution summary'!$N$7:$N$130,">0") | H22: Total | I22: =SUM(I17:I21) | J22: =SUM(J17:J21) | K22: =SUM(K17:K21) | L22: =SUM(L17:L21) | M22: =SUM(M17:M21)
A24: University-wide qualifying schemes: optional access vs compulsory provision
A25: Participation requirement | B25: Schemes | C25: Institutions | H25: By country
A26: Compulsory for all students (at stated level) | B26: =COUNTIFS('EL scheme register'!$C$7:$C$610,"University-wide",'EL scheme register'!$Q$7:$Q$610,A26,'EL scheme register'!$AJ$7:$AJ$610,"Yes") | C26: =SUMPRODUCT(('EL institution summary'!$A$7:$A$130<>"")/COUNTIF('EL institution summary'!$A$7:$A$130,'EL institution summary'!$A$7:$A$130&"")*(COUNTIFS('EL scheme register'!$A$7:$A$610,'EL institution summary'!$A$7:$A$130,'EL scheme register'!$C$7:$C$610,"University-wide",'EL scheme register'!$Q$7:$Q$610,A26,'EL scheme register'!$AJ$7:$AJ$610,"Yes")>0)) | H26: Country | I26: In scope | J26: Reviewed | K26: With ≥1 qualifying | L26: Qualifying schemes
A27: Compulsory within specified programmes | B27: =COUNTIFS('EL scheme register'!$C$7:$C$610,"University-wide",'EL scheme register'!$Q$7:$Q$610,A27,'EL scheme register'!$AJ$7:$AJ$610,"Yes") | C27: =SUMPRODUCT(('EL institution summary'!$A$7:$A$130<>"")/COUNTIF('EL institution summary'!$A$7:$A$130,'EL institution summary'!$A$7:$A$130&"")*(COUNTIFS('EL scheme register'!$A$7:$A$610,'EL institution summary'!$A$7:$A$130,'EL scheme register'!$C$7:$C$610,"University-wide",'EL scheme register'!$Q$7:$Q$610,A27,'EL scheme register'!$AJ$7:$AJ$610,"Yes")>0)) | H27: Australia | I27: =COUNTIF('EL institution summary'!$C$7:$C$130,H27) | J27: =COUNTIFS('EL institution summary'!$C$7:$C$130,H27,'EL institution summary'!$H$7:$H$130,"<>Not started") | K27: =COUNTIFS('EL institution summary'!$C$7:$C$130,H27,'EL institution summary'!$N$7:$N$130,">0") | L27: =COUNTIFS('EL scheme register'!$AO$7:$AO$610,H27,'EL scheme register'!$AJ$7:$AJ$610,"Yes")
A28: Optional/elective | B28: =COUNTIFS('EL scheme register'!$C$7:$C$610,"University-wide",'EL scheme register'!$Q$7:$Q$610,A28,'EL scheme register'!$AJ$7:$AJ$610,"Yes") | C28: =SUMPRODUCT(('EL institution summary'!$A$7:$A$130<>"")/COUNTIF('EL institution summary'!$A$7:$A$130,'EL institution summary'!$A$7:$A$130&"")*(COUNTIFS('EL scheme register'!$A$7:$A$610,'EL institution summary'!$A$7:$A$130,'EL scheme register'!$C$7:$C$610,"University-wide",'EL scheme register'!$Q$7:$Q$610,A28,'EL scheme register'!$AJ$7:$AJ$610,"Yes")>0)) | H28: UK | I28: =COUNTIF('EL institution summary'!$C$7:$C$130,H28) | J28: =COUNTIFS('EL institution summary'!$C$7:$C$130,H28,'EL institution summary'!$H$7:$H$130,"<>Not started") | K28: =COUNTIFS('EL institution summary'!$C$7:$C$130,H28,'EL institution summary'!$N$7:$N$130,">0") | L28: =COUNTIFS('EL scheme register'!$AO$7:$AO$610,H28,'EL scheme register'!$AJ$7:$AJ$610,"Yes")
A29: Selective/competitive | B29: =COUNTIFS('EL scheme register'!$C$7:$C$610,"University-wide",'EL scheme register'!$Q$7:$Q$610,A29,'EL scheme register'!$AJ$7:$AJ$610,"Yes") | C29: =SUMPRODUCT(('EL institution summary'!$A$7:$A$130<>"")/COUNTIF('EL institution summary'!$A$7:$A$130,'EL institution summary'!$A$7:$A$130&"")*(COUNTIFS('EL scheme register'!$A$7:$A$610,'EL institution summary'!$A$7:$A$130,'EL scheme register'!$C$7:$C$610,"University-wide",'EL scheme register'!$Q$7:$Q$610,A29,'EL scheme register'!$AJ$7:$AJ$610,"Yes")>0)) | H29: US | I29: =COUNTIF('EL institution summary'!$C$7:$C$130,H29) | J29: =COUNTIFS('EL institution summary'!$C$7:$C$130,H29,'EL institution summary'!$H$7:$H$130,"<>Not started") | K29: =COUNTIFS('EL institution summary'!$C$7:$C$130,H29,'EL institution summary'!$N$7:$N$130,">0") | L29: =COUNTIFS('EL scheme register'!$AO$7:$AO$610,H29,'EL scheme register'!$AJ$7:$AJ$610,"Yes")
A30: Unclear | B30: =COUNTIFS('EL scheme register'!$C$7:$C$610,"University-wide",'EL scheme register'!$Q$7:$Q$610,A30,'EL scheme register'!$AJ$7:$AJ$610,"Yes") | C30: =SUMPRODUCT(('EL institution summary'!$A$7:$A$130<>"")/COUNTIF('EL institution summary'!$A$7:$A$130,'EL institution summary'!$A$7:$A$130&"")*(COUNTIFS('EL scheme register'!$A$7:$A$610,'EL institution summary'!$A$7:$A$130,'EL scheme register'!$C$7:$C$610,"University-wide",'EL scheme register'!$Q$7:$Q$610,A30,'EL scheme register'!$AJ$7:$AJ$610,"Yes")>0)) | H30: Belgium | I30: =COUNTIF('EL institution summary'!$C$7:$C$130,H30) | J30: =COUNTIFS('EL institution summary'!$C$7:$C$130,H30,'EL institution summary'!$H$7:$H$130,"<>Not started") | K30: =COUNTIFS('EL institution summary'!$C$7:$C$130,H30,'EL institution summary'!$N$7:$N$130,">0") | L30: =COUNTIFS('EL scheme register'!$AO$7:$AO$610,H30,'EL scheme register'!$AJ$7:$AJ$610,"Yes")
H31: Denmark | I31: =COUNTIF('EL institution summary'!$C$7:$C$130,H31) | J31: =COUNTIFS('EL institution summary'!$C$7:$C$130,H31,'EL institution summary'!$H$7:$H$130,"<>Not started") | K31: =COUNTIFS('EL institution summary'!$C$7:$C$130,H31,'EL institution summary'!$N$7:$N$130,">0") | L31: =COUNTIFS('EL scheme register'!$AO$7:$AO$610,H31,'EL scheme register'!$AJ$7:$AJ$610,"Yes")
A32: Current qualifying schemes by external partner type (business-linked vs public/community) | H32: Finland | I32: =COUNTIF('EL institution summary'!$C$7:$C$130,H32) | J32: =COUNTIFS('EL institution summary'!$C$7:$C$130,H32,'EL institution summary'!$H$7:$H$130,"<>Not started") | K32: =COUNTIFS('EL institution summary'!$C$7:$C$130,H32,'EL institution summary'!$N$7:$N$130,">0") | L32: =COUNTIFS('EL scheme register'!$AO$7:$AO$610,H32,'EL scheme register'!$AJ$7:$AJ$610,"Yes")
A33: Partner type | B33: Schemes | C33: Institutions | H33: France | I33: =COUNTIF('EL institution summary'!$C$7:$C$130,H33) | J33: =COUNTIFS('EL institution summary'!$C$7:$C$130,H33,'EL institution summary'!$H$7:$H$130,"<>Not started") | K33: =COUNTIFS('EL institution summary'!$C$7:$C$130,H33,'EL institution summary'!$N$7:$N$130,">0") | L33: =COUNTIFS('EL scheme register'!$AO$7:$AO$610,H33,'EL scheme register'!$AJ$7:$AJ$610,"Yes")
A34: Business/commercial | B34: =COUNTIFS('EL scheme register'!$AB$7:$AB$610,A34,'EL scheme register'!$AJ$7:$AJ$610,"Yes") | C34: =SUMPRODUCT(('EL institution summary'!$A$7:$A$130<>"")/COUNTIF('EL institution summary'!$A$7:$A$130,'EL institution summary'!$A$7:$A$130&"")*(COUNTIFS('EL scheme register'!$A$7:$A$610,'EL institution summary'!$A$7:$A$130,'EL scheme register'!$AB$7:$AB$610,A34,'EL scheme register'!$AJ$7:$AJ$610,"Yes")>0)) | H34: Germany | I34: =COUNTIF('EL institution summary'!$C$7:$C$130,H34) | J34: =COUNTIFS('EL institution summary'!$C$7:$C$130,H34,'EL institution summary'!$H$7:$H$130,"<>Not started") | K34: =COUNTIFS('EL institution summary'!$C$7:$C$130,H34,'EL institution summary'!$N$7:$N$130,">0") | L34: =COUNTIFS('EL scheme register'!$AO$7:$AO$610,H34,'EL scheme register'!$AJ$7:$AJ$610,"Yes")
A35: Public sector | B35: =COUNTIFS('EL scheme register'!$AB$7:$AB$610,A35,'EL scheme register'!$AJ$7:$AJ$610,"Yes") | C35: =SUMPRODUCT(('EL institution summary'!$A$7:$A$130<>"")/COUNTIF('EL institution summary'!$A$7:$A$130,'EL institution summary'!$A$7:$A$130&"")*(COUNTIFS('EL scheme register'!$A$7:$A$610,'EL institution summary'!$A$7:$A$130,'EL scheme register'!$AB$7:$AB$610,A35,'EL scheme register'!$AJ$7:$AJ$610,"Yes")>0)) | H35: Ireland | I35: =COUNTIF('EL institution summary'!$C$7:$C$130,H35) | J35: =COUNTIFS('EL institution summary'!$C$7:$C$130,H35,'EL institution summary'!$H$7:$H$130,"<>Not started") | K35: =COUNTIFS('EL institution summary'!$C$7:$C$130,H35,'EL institution summary'!$N$7:$N$130,">0") | L35: =COUNTIFS('EL scheme register'!$AO$7:$AO$610,H35,'EL scheme register'!$AJ$7:$AJ$610,"Yes")
A36: Charity/community | B36: =COUNTIFS('EL scheme register'!$AB$7:$AB$610,A36,'EL scheme register'!$AJ$7:$AJ$610,"Yes") | C36: =SUMPRODUCT(('EL institution summary'!$A$7:$A$130<>"")/COUNTIF('EL institution summary'!$A$7:$A$130,'EL institution summary'!$A$7:$A$130&"")*(COUNTIFS('EL scheme register'!$A$7:$A$610,'EL institution summary'!$A$7:$A$130,'EL scheme register'!$AB$7:$AB$610,A36,'EL scheme register'!$AJ$7:$AJ$610,"Yes")>0)) | H36: Italy | I36: =COUNTIF('EL institution summary'!$C$7:$C$130,H36) | J36: =COUNTIFS('EL institution summary'!$C$7:$C$130,H36,'EL institution summary'!$H$7:$H$130,"<>Not started") | K36: =COUNTIFS('EL institution summary'!$C$7:$C$130,H36,'EL institution summary'!$N$7:$N$130,">0") | L36: =COUNTIFS('EL scheme register'!$AO$7:$AO$610,H36,'EL scheme register'!$AJ$7:$AJ$610,"Yes")
A37: Mixed | B37: =COUNTIFS('EL scheme register'!$AB$7:$AB$610,A37,'EL scheme register'!$AJ$7:$AJ$610,"Yes") | C37: =SUMPRODUCT(('EL institution summary'!$A$7:$A$130<>"")/COUNTIF('EL institution summary'!$A$7:$A$130,'EL institution summary'!$A$7:$A$130&"")*(COUNTIFS('EL scheme register'!$A$7:$A$610,'EL institution summary'!$A$7:$A$130,'EL scheme register'!$AB$7:$AB$610,A37,'EL scheme register'!$AJ$7:$AJ$610,"Yes")>0)) | H37: Netherlands | I37: =COUNTIF('EL institution summary'!$C$7:$C$130,H37) | J37: =COUNTIFS('EL institution summary'!$C$7:$C$130,H37,'EL institution summary'!$H$7:$H$130,"<>Not started") | K37: =COUNTIFS('EL institution summary'!$C$7:$C$130,H37,'EL institution summary'!$N$7:$N$130,">0") | L37: =COUNTIFS('EL scheme register'!$AO$7:$AO$610,H37,'EL scheme register'!$AJ$7:$AJ$610,"Yes")
A38: Other | B38: =COUNTIFS('EL scheme register'!$AB$7:$AB$610,A38,'EL scheme register'!$AJ$7:$AJ$610,"Yes") | C38: =SUMPRODUCT(('EL institution summary'!$A$7:$A$130<>"")/COUNTIF('EL institution summary'!$A$7:$A$130,'EL institution summary'!$A$7:$A$130&"")*(COUNTIFS('EL scheme register'!$A$7:$A$610,'EL institution summary'!$A$7:$A$130,'EL scheme register'!$AB$7:$AB$610,A38,'EL scheme register'!$AJ$7:$AJ$610,"Yes")>0)) | H38: Spain | I38: =COUNTIF('EL institution summary'!$C$7:$C$130,H38) | J38: =COUNTIFS('EL institution summary'!$C$7:$C$130,H38,'EL institution summary'!$H$7:$H$130,"<>Not started") | K38: =COUNTIFS('EL institution summary'!$C$7:$C$130,H38,'EL institution summary'!$N$7:$N$130,">0") | L38: =COUNTIFS('EL scheme register'!$AO$7:$AO$610,H38,'EL scheme register'!$AJ$7:$AJ$610,"Yes")
A39: Unclear | B39: =COUNTIFS('EL scheme register'!$AB$7:$AB$610,A39,'EL scheme register'!$AJ$7:$AJ$610,"Yes") | C39: =SUMPRODUCT(('EL institution summary'!$A$7:$A$130<>"")/COUNTIF('EL institution summary'!$A$7:$A$130,'EL institution summary'!$A$7:$A$130&"")*(COUNTIFS('EL scheme register'!$A$7:$A$610,'EL institution summary'!$A$7:$A$130,'EL scheme register'!$AB$7:$AB$610,A39,'EL scheme register'!$AJ$7:$AJ$610,"Yes")>0)) | H39: Sweden | I39: =COUNTIF('EL institution summary'!$C$7:$C$130,H39) | J39: =COUNTIFS('EL institution summary'!$C$7:$C$130,H39,'EL institution summary'!$H$7:$H$130,"<>Not started") | K39: =COUNTIFS('EL institution summary'!$C$7:$C$130,H39,'EL institution summary'!$N$7:$N$130,">0") | L39: =COUNTIFS('EL scheme register'!$AO$7:$AO$610,H39,'EL scheme register'!$AJ$7:$AJ$610,"Yes")
A40: None | B40: =COUNTIFS('EL scheme register'!$AB$7:$AB$610,A40,'EL scheme register'!$AJ$7:$AJ$610,"Yes") | C40: =SUMPRODUCT(('EL institution summary'!$A$7:$A$130<>"")/COUNTIF('EL institution summary'!$A$7:$A$130,'EL institution summary'!$A$7:$A$130&"")*(COUNTIFS('EL scheme register'!$A$7:$A$610,'EL institution summary'!$A$7:$A$130,'EL scheme register'!$AB$7:$AB$610,A40,'EL scheme register'!$AJ$7:$AJ$610,"Yes")>0))
A42: Evidence status of all register records (counted schemes only; umbrellas excluded)
A43: Category | B43: Records
A44: Meets all three; current delivery confirmed | B44: =COUNTIFS('EL scheme register'!$AF$7:$AF$610,"Meets all three",'EL scheme register'!$AG$7:$AG$610,"Current delivery confirmed",'EL scheme register'!$AI$7:$AI$610,"Yes")
A45: Meets all three; current status unclear | B45: =COUNTIFS('EL scheme register'!$AF$7:$AF$610,"Meets all three",'EL scheme register'!$AG$7:$AG$610,"Current status unclear",'EL scheme register'!$AI$7:$AI$610,"Yes")
A46: Meets all three; historical / paused only | B46: =COUNTIFS('EL scheme register'!$AF$7:$AF$610,"Meets all three",'EL scheme register'!$AG$7:$AG$610,"Historical delivery only",'EL scheme register'!$AI$7:$AI$610,"Yes")+COUNTIFS('EL scheme register'!$AF$7:$AF$610,"Meets all three",'EL scheme register'!$AG$7:$AG$610,"Paused/discontinued",'EL scheme register'!$AI$7:$AI$610,"Yes")
A47: Meets all three; announced / forthcoming | B47: =COUNTIFS('EL scheme register'!$AF$7:$AF$610,"Meets all three",'EL scheme register'!$AG$7:$AG$610,"Announced/forthcoming",'EL scheme register'!$AI$7:$AI$610,"Yes")
A48: Potentially relevant; evidence incomplete | B48: =COUNTIFS('EL scheme register'!$AF$7:$AF$610,"Potentially relevant; evidence incomplete",'EL scheme register'!$AI$7:$AI$610,"Yes")
...

Sheet EL institution summary
A2: Experiential learning: institution summary
A3: One row per institution in the 124-institution sample. Counts are live formulas over 'EL scheme register' (column AJ = counted, meets all three, current).
A4: Findings within the researched sample, not national prevalence estimates. 'Not started' / 'Partial' institutions must not be read as negative findings. No composite score is used.
A6: Institution ID | B6: Institution | C6: Country | D6: Sample group | E6: Region group | F6: QS edition | G6: QS rank | H6: Review completeness | I6: Qualifying current: University-wide | J6: Qualifying current: Cross-faculty | K6: Qualifying current: Faculty/school | L6: Qualifying current: Programme/course | M6: Qualifying current: Unclear reach | N6: Qualifying current: total | O6: Evidence-incomplete records | P6: Outside-definition records in register | Q6: Exclusions / near-misses | R6: University-wide access evidenced (qualifying current scheme) | S6: Compulsory university-wide provision evidenced | T6: Main qualifying schemes | U6: Distribution across faculty areas (qualifying current) | V6: How embedded the provision appears | W6: Concise assessment | X6: Material gaps and unresolved questions
A7: RG01 | B7: Birmingham | C7: UK | D7: Russell Group | E7: UK – Russell Group | F7: 2027 | G7: 68 | H7: Complete | I7: =COUNTIFS('EL scheme register'!$A$7:$A$610,$A7,'EL scheme register'!$C$7:$C$610,"University-wide",'EL scheme register'!$AJ$7:$AJ$610,"Yes") | J7: =COUNTIFS('EL scheme register'!$A$7:$A$610,$A7,'EL scheme register'!$C$7:$C$610,"Cross-faculty",'EL scheme register'!$AJ$7:$AJ$610,"Yes") | K7: =COUNTIFS('EL scheme register'!$A$7:$A$610,$A7,'EL scheme register'!$C$7:$C$610,"Faculty/school",'EL scheme register'!$AJ$7:$AJ$610,"Yes") | L7: =COUNTIFS('EL scheme register'!$A$7:$A$610,$A7,'EL scheme register'!$C$7:$C$610,"Programme/course",'EL scheme register'!$AJ$7:$AJ$610,"Yes") | M7: =COUNTIFS('EL scheme register'!$A$7:$A$610,$A7,'EL scheme register'!$C$7:$C$610,"Unclear",'EL scheme register'!$AJ$7:$AJ$610,"Yes") | N7: =SUM(I7:M7) | O7: =COUNTIFS('EL scheme register'!$A$7:$A$610,$A7,'EL scheme register'!$AF$7:$AF$610,"Potentially relevant; evidence incomplete",'EL scheme register'!$AI$7:$AI$610,"Yes") | P7: =COUNTIFS('EL scheme register'!$A$7:$A$610,$A7,'EL scheme register'!$AF$7:$AF$610,"Outside strict definition") | Q7: =COUNTIF('EL exclusions & gaps'!$B$7:$B$5000,$A7) | R7: Yes | S7: Not evidenced | T7: The Birmingham Project [University-wide]; Masters Consultancy Challenge (MCC) [University-wide]; Impact Challenge [University-wide]; Capgemini Community Challenge [Cross-faculty] | U7: Central provision: 3; Business/management: 1; Engineering/computing: 1; Science: 1 | V7: Several distributed routes | W7: Birmingham has several distributed live-project routes. Most are short, extracurricular and centrally run, with smaller programme-embedded provision in the Business School. - Central (Careers Network): - The Birmingham Project is open to all first-year undergraduates on the Edgbaston campus. It is optional, non-credit and recorded as pass/fail on the transcript. Interdisciplinary teams spend one full-time week in June on challenges set by 7–8 employer partners in 2026 (e.g. HSBC, Siemens, Transport for West Midlands, West Midlands Combined Authority). Each challenge has an industry professional, and teams finish with a group video presentation to industry and academics. More than 2,000 students have taken part since 2013. - The Masters Consultancy Challenge is selective and open to taught postgraduates. Interdisciplinary groups work for 3 weeks on a Turner & Townsend challenge and present to an industry and University panel. - The Impact Challenge is a paid, week-long programme for widening-participation finalists and penultimate-year students. Teams work on employer-set projects, mostly for charities and social enterprises. - Business School: - The Capgemini Community Challenge is | X7: Further departmental instances likely. Engineering group design projects lack evidence of industry-set briefs. Current-year evidence missing for SMC MSc and Company Projects. Maths Mathematical Challenge module partner/team format unverified. Education, Psychology and Biosciences only lightly searched. Birmingham Project partner count conflict (7 vs 8). Capgemini eligibility conflict.
A8: RG02 | B8: Bristol | C8: UK | D8: Russell Group | E8: UK – Russell Group | F8: 2027 | G8: 57 | H8: Complete | I8: =COUNTIFS('EL scheme register'!$A$7:$A$610,$A8,'EL scheme register'!$C$7:$C$610,"University-wide",'EL scheme register'!$AJ$7:$AJ$610,"Yes") | J8: =COUNTIFS('EL scheme register'!$A$7:$A$610,$A8,'EL scheme register'!$C$7:$C$610,"Cross-faculty",'EL scheme register'!$AJ$7:$AJ$610,"Yes") | K8: =COUNTIFS('EL scheme register'!$A$7:$A$610,$A8,'EL scheme register'!$C$7:$C$610,"Faculty/school",'EL scheme register'!$AJ$7:$AJ$610,"Yes") | L8: =COUNTIFS('EL scheme register'!$A$7:$A$610,$A8,'EL scheme register'!$C$7:$C$610,"Programme/course",'EL scheme register'!$AJ$7:$AJ$610,"Yes") | M8: =COUNTIFS('EL scheme register'!$A$7:$A$610,$A8,'EL scheme register'!$C$7:$C$610,"Unclear",'EL scheme register'!$AJ$7:$AJ$610,"Yes") | N8: =SUM(I8:M8) | O8: =COUNTIFS('EL scheme register'!$A$7:$A$610,$A8,'EL scheme register'!$AF$7:$AF$610,"Potentially relevant; evidence incomplete",'EL scheme register'!$AI$7:$AI$610,"Yes") | P8: =COUNTIFS('EL scheme register'!$A$7:$A$610,$A8,'EL scheme register'!$AF$7:$AF$610,"Outside strict definition") | Q8: =COUNTIF('EL exclusions & gaps'!$B$7:$B$5000,$A8) | R8: Not evidenced | S8: Not evidenced | T8: Mathematical and Data Modelling 3 (SEMT30005) [Programme/course]; Management Consultancy (EFIM30064) [Programme/course]; Business School Micro-Internship programme [Faculty/school]; The Marketing Applied Extended Project (AEP) - applied group route (MSc Marketing) (MGRCM0040) [Programme/course]; Human Rights Law Clinic (Human Rights Implementation Centre) [Faculty/school] | U8: Business/management: 3; Engineering/computing: 1; Other (law, health, design, architecture…): 1 | V8: Several distributed routes | W8: Bristol has no university-wide, compulsory employer-project scheme; qualifying provision is distributed across schools, with the Industrial Liaison Office (Faculty of Science and Engineering) acting as the main broker of client briefs. Verified current routes. Engineering Mathematics' Mathematical and Data Modelling 3 (2026/27) puts groups of 4-6 on three six-week problems, two supplied by industrial partners. The Business School's final-year Management Consultancy (EFIM30064, 2025/26) places groups of 4-6 on briefs from outside organisations, mostly charities. The Business School Micro-Internship (200 Masters places, 3 weeks, extracurricular) assigns random teams to an industry client. The MSc Marketing applied project (small group, external commercial/third-sector partners) and the Law School's selective Human Rights Law Clinic (student-led teams researching to partner briefs, ~70 members) are also current. Credible but not currently evidenced. Undergraduate Software Engineering Project and MSc Summer Team Project (client-proposed, teams of 4-6) rest on undated ILO pages; Geography's Consultancy Project (3-5 student teams, external clients) appears only in a mislabelled catalogue | X8: Further departmental instances likely (Aerospace/Electrical MEng industrial group design projects, Computer Science AI software team project, other MSc business projects, Veterinary/Medicine/Dentistry/Architecture community or client projects not found). Unit catalogue results often carry unreliable future year labels (2031-2038) so several units lack genuine current-year evidence. Partner names and cohort sizes mostly unpublished. Humanities/social science client-team units not found. 38 searches used; Open Unit lists not examined unit by unit.
A9: RG03 | B9: Cambridge | C9: UK | D9: Russell Group | E9: UK – Russell Group | F9: 2027 | G9: 6 | H9: Complete | I9: =COUNTIFS('EL scheme register'!$A$7:$A$610,$A9,'EL scheme register'!$C$7:$C$610,"University-wide",'EL scheme register'!$AJ$7:$AJ$610,"Yes") | J9: =COUNTIFS('EL scheme register'!$A$7:$A$610,$A9,'EL scheme register'!$C$7:$C$610,"Cross-faculty",'EL scheme register'!$AJ$7:$AJ$610,"Yes") | K9: =COUNTIFS('EL scheme register'!$A$7:$A$610,$A9,'EL scheme register'!$C$7:$C$610,"Faculty/school",'EL scheme register'!$AJ$7:$AJ$610,"Yes") | L9: =COUNTIFS('EL scheme register'!$A$7:$A$610,$A9,'EL scheme register'!$C$7:$C$610,"Programme/course",'EL scheme register'!$AJ$7:$AJ$610,"Yes") | M9: =COUNTIFS('EL scheme register'!$A$7:$A$610,$A9,'EL scheme register'!$C$7:$C$610,"Unclear",'EL scheme register'!$AJ$7:$AJ$610,"Yes") | N9: =SUM(I9:M9) | O9: =COUNTIFS('EL scheme register'!$A$7:$A$610,$A9,'EL scheme register'!$AF$7:$AF$610,"Potentially relevant; evidence incomplete",'EL scheme register'!$AI$7:$AI$610,"Yes") | P9: =COUNTIFS('EL scheme register'!$A$7:$A$610,$A9,'EL scheme register'!$AF$7:$AF$610,"Outside strict definition") | Q9: =COUNTIF('EL exclusions & gaps'!$B$7:$B$5000,$A9) | R9: Not evidenced | S9: Not evidenced | T9: MBA Global Consulting Project (GCP) [Programme/course]; MBA Cambridge Venture Project (CVP) [Programme/course]; MFin Group Consulting Project (GCP) [Programme/course]; MPhil in Management: Management Consulting Project [Programme/course]; Management Studies Tripos (MST) consulting project [Programme/course]; MPhil in Technology Policy: Final Group Project [Programme/course]; Computer Science Tripos Part IB Group Project [Programme/course] | U9: Business/management: 6; Engineering/computing: 2 | V9: Several distributed routes | W9: Cambridge has no institution-wide employer-project scheme; provision is concentrated in a few programme-embedded routes. Cambridge Judge Business School runs the densest set: the MBA Global Consulting Project (4-5 students, ~4 weeks, hosts such as WHO and Uber) and Cambridge Venture Project (5-6 students, ~6 weeks, local businesses), the MFin Group Consulting Project, the MPhil in Management Consulting Project, the undergraduate Management Studies Tripos project (teams of 3-4 for external organisations), and the MPhil in Technology Policy Final Group Project (clients including Cabinet Office, Ofcom, Arm). Each is part of a degree, uses a central client-proposal process with 2026/27 calls, and relies on external organisations as clients who receive the output. Outside business, the Computer Science Tripos Part IB group project is the standout: a compulsory seven-week team project for an assigned industry client, with 2026 clients including Nokia Bell Labs and Bending Spoons. Further routes exist in Engineering (IfM MET/ISMM company projects, ESD MPhil Client Project), Bioscience Enterprise and Public Policy/Conservation Leadership, but these lack dated current evidence. The universi | X9: Further departmental instances likely (other MPhils, Engineering Part IIA group projects, Chemical Engineering, Medicine, Architecture, Law, Education not individually searched). Credit/weighting and 'compulsory' wording not retrieved for most JBS projects (inferred from core-curriculum placement). MET/ISMM, ESD, MBE, Bennett PAE and Conservation Leadership need dated 2025/26-2026/27 corroboration. Student societies (180 Degrees Consulting, Cambridge Consulting Network) and Cambridge Hub not verified. WebFetch unavailable; all evidence is search-index extract/paraphrase.
A10: RG04 | B10: Cardiff | C10: UK | D10: Russell Group | E10: UK – Russell Group | F10: 2027 | G10: 179 | H10: Complete | I10: =COUNTIFS('EL scheme register'!$A$7:$A$610,$A10,'EL scheme register'!$C$7:$C$610,"University-wide",'EL scheme register'!$AJ$7:$AJ$610,"Yes") | J10: =COUNTIFS('EL scheme register'!$A$7:$A$610,$A10,'EL scheme register'!$C$7:$C$610,"Cross-faculty",'EL scheme register'!$AJ$7:$AJ$610,"Yes") | K10: =COUNTIFS('EL scheme register'!$A$7:$A$610,$A10,'EL scheme register'!$C$7:$C$610,"Faculty/school",'EL scheme register'!$AJ$7:$AJ$610,"Yes") | L10: =COUNTIFS('EL scheme register'!$A$7:$A$610,$A10,'EL scheme register'!$C$7:$C$610,"Programme/course",'EL scheme register'!$AJ$7:$AJ$610,"Yes") | M10: =COUNTIFS('EL scheme register'!$A$7:$A$610,$A10,'EL scheme register'!$C$7:$C$610,"Unclear",'EL scheme register'!$AJ$7:$AJ$610,"Yes") | N10: =SUM(I10:M10) | O10: =COUNTIFS('EL scheme register'!$A$7:$A$610,$A10,'EL scheme register'!$AF$7:$AF$610,"Potentially relevant; evidence incomplete",'EL scheme register'!$AI$7:$AI$610,"Yes") | P10: =COUNTIFS('EL scheme register'!$A$7:$A$610,$A10,'EL scheme register'!$AF$7:$AF$610,"Outside strict definition") | Q10: =COUNTIF('EL exclusions & gaps'!$B$7:$B$5000,$A10) | R10: Not evidenced | S10: Not evidenced | T10: BSc Applied Software Engineering: client-based team projects (National Software Academy) [Programme/course] | U10: Engineering/computing: 1 | V10: Several distributed routes | W10: Cardiff has employer-linked group project provision concentrated in computing and the Business School (mostly postgraduate). No university-wide route was verified. - Clearest current route: the National Software Academy's BSc Applied Software Engineering builds team client projects into the degree. Teams build software for real private, public and third-sector clients over projects of about four weeks, meeting clients fortnightly (2026-entry page). - Business School: - The MSc Strategic Entrepreneurship and Innovation New Venture Plan (BST413, 40 credits; optional instead of a dissertation) assigns each group a real company client that sets the brief. - The MBA Management Consultancy elective, co-run with PA Consulting, sends teams to Welsh charities (e.g. Tenovus Cancer Care, WCVA). - The current status of both is undated. - The MBA live/Accelerator project (corporate client) and the MSc Business Management Consultancy Challenge (charity clients only 'may') are incomplete on group work or external coverage. - Planning: MSc Spatial Planning Live Project CPT831 has real clients such as planning authorities (group work unconfirmed). An older UG group consultancy module (CP0210) is ev | X10: Review is Partial (see partial_remaining). Key gaps: health schools not searched; science covered by one search only; group structure for MBA live project, MSc SPD Live Project and architecture live projects; whether MSc Business Management Consultancy Challenge always has an external client; dated 2025/26 evidence for Business School routes; whether engineering MSc group projects routinely have company partners and on which programmes; Bremen-Cardiff eligibility and any external problem owner; Student Enterprise annual report content; FinTech Wales Skills Challenge and Public Value Hackathon format. Further departmental instances are likely (e.g. NSA MSc Software Engineering, Computer Science MSc, Journalism). Reduced-depth round: WebFetch returned 403 for cardiff.ac.uk so no page text was obtained; health schools and Journalism remain unverified after one search.
A11: RG05 | B11: Durham | C11: UK | D11: Russell Group | E11: UK – Russell Group | F11: 2027 | G11: 85 | H11: Complete | I11: =COUNTIFS('EL scheme register'!$A$7:$A$610,$A11,'EL scheme register'!$C$7:$C$610,"University-wide",'EL scheme register'!$AJ$7:$AJ$610,"Yes") | J11: =COUNTIFS('EL scheme register'!$A$7:$A$610,$A11,'EL scheme register'!$C$7:$C$610,"Cross-faculty",'EL scheme register'!$AJ$7:$AJ$610,"Yes") | K11: =COUNTIFS('EL scheme register'!$A$7:$A$610,$A11,'EL scheme register'!$C$7:$C$610,"Faculty/school",'EL scheme register'!$AJ$7:$AJ$610,"Yes") | L11: =COUNTIFS('EL scheme register'!$A$7:$A$610,$A11,'EL scheme register'!$C$7:$C$610,"Programme/course",'EL scheme register'!$AJ$7:$AJ$610,"Yes") | M11: =COUNTIFS('EL scheme register'!$A$7:$A$610,$A11,'EL scheme register'!$C$7:$C$610,"Unclear",'EL scheme register'!$AJ$7:$AJ$610,"Yes") | N11: =SUM(I11:M11) | O11: =COUNTIFS('EL scheme register'!$A$7:$A$610,$A11,'EL scheme register'!$AF$7:$AF$610,"Potentially relevant; evidence incomplete",'EL scheme register'!$AI$7:$AI$610,"Yes") | P11: =COUNTIFS('EL scheme register'!$A$7:$A$610,$A11,'EL scheme register'!$AF$7:$AF$610,"Outside strict definition") | Q11: =COUNTIF('EL exclusions & gaps'!$B$7:$B$5000,$A11) | R11: Not evidenced | S11: Not evidenced | T11: COMP2281 Software Engineering (Year 2 team project with external organisation) (COMP2281) [Programme/course]; GEOL4091 Earth Sciences into Industry (GEOL4091) [Programme/course] | U11: Engineering/computing: 1; Science: 1 | V11: Several distributed routes | W11: Durham's verified employer-linked group project provision is distributed across departments rather than institution-wide, with a small central employer-facing offer. The clearest current routes are two curricular modules: COMP2281 Software Engineering (compulsory Year 2 Computer Science teams build a substantial software project in partnership with an external organisation; listed available 2025/26) and GEOL4091 Earth Sciences into Industry (optional Level 4 group project in which a client, typically an external organisation, sets the problem and deliverables and receives the groups' presented solution; 60% group report, listed 2025/26). The Physics Team Project (PHYS3581) fits closely (teams of up to six, 8 weeks, client brief, presentation to clients such as Procter & Gamble and Mantis Vacuum Systems) but problems are set by 'staff or local industry', so the external share is unproven. The central Mini Consultancy Competition (three-week, employer-set issue, three student teams) is documented only on an employer page, with no student eligibility or dated cohort. Engineering's pair-based Industrial Problem Solving live company project is only evidenced to 2019; the year-long Engin | X11: Search limit reached before checking Participatory Action Research (SOCI43715) and further arts/social science, education, health and law clinic provision. Further departmental instances likely (Engineering design/capstone with Industrial Partnership Committee partners, Biosciences, Psychology, Education). Central Mini Consultancy Competition lacks student-side eligibility, date and cohort evidence. Many sources are undated module/course pages or search-summary paraphrases of them; page contents were not opened directly. Resume pass (2026-10-13, 3 searches): Mini Consultancy student-side selection/team details still not found (employer-side page only: 3 teams, 3 weeks); MSc Business Analytics team vs individual still unconfirmed; PHYS3581 external share not stated.
A12: RG06 | B12: Edinburgh | C12: UK | D12: Russell Group | E12: UK – Russell Group | F12: 2027 | G12: 35 | H12: Complete | I12: =COUNTIFS('EL scheme register'!$A$7:$A$610,$A12,'EL scheme register'!$C$7:$C$610,"University-wide",'EL scheme register'!$AJ$7:$AJ$610,"Yes") | J12: =COUNTIFS('EL scheme register'!$A$7:$A$610,$A12,'EL scheme register'!$C$7:$C$610,"Cross-faculty",'EL scheme register'!$AJ$7:$AJ$610,"Yes") | K12: =COUNTIFS('EL scheme register'!$A$7:$A$610,$A12,'EL scheme register'!$C$7:$C$610,"Faculty/school",'EL scheme register'!$AJ$7:$AJ$610,"Yes") | L12: =COUNTIFS('EL scheme register'!$A$7:$A$610,$A12,'EL scheme register'!$C$7:$C$610,"Programme/course",'EL scheme register'!$AJ$7:$AJ$610,"Yes") | M12: =COUNTIFS('EL scheme register'!$A$7:$A$610,$A12,'EL scheme register'!$C$7:$C$610,"Unclear",'EL scheme register'!$AJ$7:$AJ$610,"Yes") | N12: =SUM(I12:M12) | O12: =COUNTIFS('EL scheme register'!$A$7:$A$610,$A12,'EL scheme register'!$AF$7:$AF$610,"Potentially relevant; evidence incomplete",'EL scheme register'!$AI$7:$AI$610,"Yes") | P12: =COUNTIFS('EL scheme register'!$A$7:$A$610,$A12,'EL scheme register'!$AF$7:$AF$610,"Outside strict definition") | Q12: =COUNTIF('EL exclusions & gaps'!$B$7:$B$5000,$A12) | R12: Not evidenced | S12: Not evidenced | T12: Students as Change Agents (EFIE08003) / EFI Change Agents (EFIE08006) (EFIE08003 / EFIE08006) [Unclear]; Sustainable Business Consultancy Projects (MSc Global Strategy and Sustainability) (CMSE11573) [Programme/course]; Enterprise Consultancy Project (BUST10120), Undergraduate Enterprise Consultancy (BUST10120) [Programme/course]; Client Consulting Project (EFIE11118), MSc Creative Industries (EFIE11118) [Programme/course]; LLM Human Rights Clinic (LLM in Human Rights) [Programme/course] | U12: Arts/humanities/social sciences: 3; Business/management: 2; Other (law, health, design, architecture…): 2; Central provision: 1 | V12: Several distributed routes | W12: Edinburgh has no institution-wide employer-project programme in operation. The one university-wide scheme, Students as Change Agents (SACHA), survives only as a 20-credit EFI course (EFIE08003 / EFIE08006) in which small interdisciplinary teams work on a challenge set by an external partner and present outputs to it; the Careers co-curricular route is paused. Whether the elective is open university-wide or restricted to the EFI Interdisciplinary Futures MA is unresolved. The densest provision is distributed in the Business School: live-client team consultancies for MSc Global Strategy and Sustainability (teams of 5-6, ten weeks, current in the 2026/27 catalogue), MSc Entrepreneurship and Innovation, MSc Climate Change Finance and Investment, the MBA (consultancy project and a one-week charity consultancy), and an undergraduate Enterprise Consultancy Project (2025/26) for a new local business. Clients propose challenges, attend scoping and presentations, and receive reports; several of these pages are undated or last evidenced before 2025. EFI MSc Creative Industries has a compulsory Client Consulting Project (cultural-organisation client, 2025/26) and a Team Project that mixes clie | X12: Further departmental instances likely (ECA live-brief modules, Business School and EFI courses not individually checked, Engineering/Informatics sponsor projects). Currency not confirmed for MCiP, Climate Change Consulting, MBA projects, Freedom of Expression Clinic, GeoSciences Outreach. SACHA/EFI Change Agents eligibility conflict. No participation numbers published. Search ceiling approached (~40); Medicine/Veterinary/Social Sciences/Moray House only lightly searched.
A13: RG07 | B13: Exeter | C13: UK | D13: Russell Group | E13: UK – Russell Group | F13: 2027 | G13: 136 | H13: Complete | I13: =COUNTIFS('EL scheme register'!$A$7:$A$610,$A13,'EL scheme register'!$C$7:$C$610,"University-wide",'EL scheme register'!$AJ$7:$AJ$610,"Yes") | J13: =COUNTIFS('EL scheme register'!$A$7:$A$610,$A13,'EL scheme register'!$C$7:$C$610,"Cross-faculty",'EL scheme register'!$AJ$7:$AJ$610,"Yes") | K13: =COUNTIFS('EL scheme register'!$A$7:$A$610,$A13,'EL scheme register'!$C$7:$C$610,"Faculty/school",'EL scheme register'!$AJ$7:$AJ$610,"Yes") | L13: =COUNTIFS('EL scheme register'!$A$7:$A$610,$A13,'EL scheme register'!$C$7:$C$610,"Programme/course",'EL scheme register'!$AJ$7:$AJ$610,"Yes") | M13: =COUNTIFS('EL scheme register'!$A$7:$A$610,$A13,'EL scheme register'!$C$7:$C$610,"Unclear",'EL scheme register'!$AJ$7:$AJ$610,"Yes") | N13: =SUM(I13:M13) | O13: =COUNTIFS('EL scheme register'!$A$7:$A$610,$A13,'EL scheme register'!$AF$7:$AF$610,"Potentially relevant; evidence incomplete",'EL scheme register'!$AI$7:$AI$610,"Yes") | P13: =COUNTIFS('EL scheme register'!$A$7:$A$610,$A13,'EL scheme register'!$AF$7:$AF$610,"Outside strict definition") | Q13: =COUNTIF('EL exclusions & gaps'!$B$7:$B$5000,$A13) | R13: Not evidenced | S13: Not evidenced | T13: Business Project (MSc Management) (BEMM149) [Programme/course] | U13: Business/management: 1 | V13: Unclear | W13: Exeter has two university-wide extracurricular routes. Embedded programme provision is mainly in the Business School. Review incomplete (search budget exhausted). - Grand Challenges (legacy): a free June project week open to all undergraduates. Groups of normally 4-8 design solutions to themed real-world challenges and present them to expert panels. 2026 challenge pages confirm current delivery. External input is largely experts giving lectures or sitting in the audience, so C is Unclear. The exception is a 2026 Industry-led Enquiry Group with Amazon Web Services, but AWS's exact role was not evidenced. - Future17 (legacy, with QS): open to undergraduates in year 2 or later and to PGT students. International teams of 6-8 spend 12 weeks on challenges set by partner organisations; 31 organisations offered 44 challenges in one round. A partner representative sits on the assessment panel. It can be taken for 15 credits via APEL or without credit. It meets all three criteria, but the latest dated cohort is about 2024/25, so its status is unclear. - Business School: the compulsory BEMM149 Business Project on MSc Management is a group consultancy project on a partner's brief, with a repor | X13: Other area unsearched; AHSS barely searched; dated current evidence missing for Future17 and BEMM149; AWS role in Grand Challenges; ECMM427 customer; group format for BEP3020, MSc MBA consulting option, Sports Consultancy Project; One Planet MBA team challenges; further departmental instances likely (engineering, business MSc programmes). Medicine/Health, Psychology, Sport not separately searched; reduced-depth mode.
A14: RG08 | B14: Glasgow | C14: UK | D14: Russell Group | E14: UK – Russell Group | F14: 2027 | G14: 80 | H14: Complete | I14: =COUNTIFS('EL scheme register'!$A$7:$A$610,$A14,'EL scheme register'!$C$7:$C$610,"University-wide",'EL scheme register'!$AJ$7:$AJ$610,"Yes") | J14: =COUNTIFS('EL scheme register'!$A$7:$A$610,$A14,'EL scheme register'!$C$7:$C$610,"Cross-faculty",'EL scheme register'!$AJ$7:$AJ$610,"Yes") | K14: =COUNTIFS('EL scheme register'!$A$7:$A$610,$A14,'EL scheme register'!$C$7:$C$610,"Faculty/school",'EL scheme register'!$AJ$7:$AJ$610,"Yes") | L14: =COUNTIFS('EL scheme register'!$A$7:$A$610,$A14,'EL scheme register'!$C$7:$C$610,"Programme/course",'EL scheme register'!$AJ$7:$AJ$610,"Yes") | M14: =COUNTIFS('EL scheme register'!$A$7:$A$610,$A14,'EL scheme register'!$C$7:$C$610,"Unclear",'EL scheme register'!$AJ$7:$AJ$610,"Yes") | N14: =SUM(I14:M14) | O14: =COUNTIFS('EL scheme register'!$A$7:$A$610,$A14,'EL scheme register'!$AF$7:$AF$610,"Potentially relevant; evidence incomplete",'EL scheme register'!$AI$7:$AI$610,"Yes") | P14: =COUNTIFS('EL scheme register'!$A$7:$A$610,$A14,'EL scheme register'!$AF$7:$AF$610,"Outside strict definition") | Q14: =COUNTIF('EL exclusions & gaps'!$B$7:$B$5000,$A14) | R14: Not evidenced | S14: Not evidenced | T14: MBA Group Consultancy Project (BUS5052) [Programme/course]; Integrating Business and Management in Practice (MGT4091) [Programme/course]; International Management Solutions (MGT5181) [Programme/course]; Team Project 3 (Software Team Project) (COMPSCI3004) [Programme/course] | U14: Business/management: 3; Engineering/computing: 1 | V14: Several distributed routes | W14: Glasgow's qualifying provision is programme-embedded, concentrated in the Adam Smith Business School with one computing route; nothing university-wide was verified. - MBA Group Consultancy Project (BUS5052, 2026-27): MBA groups manage a client and respond to a client brief over ~70 hours in two weeks; group report (65%) and 30-minute presentation (35%). - International Management Solutions (MGT5181, 2026-27): MSc International Business teams run a live consultancy for firms seeking to internationalise; group report and presentation; client introduction meeting. - Integrating Business and Management in Practice (MGT4091, 2025-26): Honours capstone in one intensive week; groups meet a live client and present recommendations to them. Probably the Honours core 'integrative experiential learning course', but not confirmed. - Team Project 3 (COMPSCI3004, 2026-27): 30-credit, year-long third-year team software project for real customers who submit projects and select teams. Customer sector and internal/external mix are not stated. - Entrepreneurial Ventures Management & Growth (MGT4019): teams of 4-5 consult for real charity/social-enterprise clients with consultant mentors; current deliv | X14: Compulsory vs optional status unknown for S2-S5. Client names/sectors not evidenced (S5 customer type unclear). MGT4091 link to the UG 'Small Business Consultancy Project' course card unconfirmed. MGT4019 current delivery unconfirmed. Engineering design/industrial projects, MSc Environment & Sustainable Development consultancy, College of Social Sciences consultation projects not verified (reduced-depth). Further departmental instances likely.
A15: RG09 | B15: Imperial College London | C15: UK | D15: Russell Group | E15: UK – Russell Group | F15: 2027 | G15: 2 | H15: Complete | I15: =COUNTIFS('EL scheme register'!$A$7:$A$610,$A15,'EL scheme register'!$C$7:$C$610,"University-wide",'EL scheme register'!$AJ$7:$AJ$610,"Yes") | J15: =COUNTIFS('EL scheme register'!$A$7:$A$610,$A15,'EL scheme register'!$C$7:$C$610,"Cross-faculty",'EL scheme register'!$AJ$7:$AJ$610,"Yes") | K15: =COUNTIFS('EL scheme register'!$A$7:$A$610,$A15,'EL scheme register'!$C$7:$C$610,"Faculty/school",'EL scheme register'!$AJ$7:$AJ$610,"Yes") | L15: =COUNTIFS('EL scheme register'!$A$7:$A$610,$A15,'EL scheme register'!$C$7:$C$610,"Programme/course",'EL scheme register'!$AJ$7:$AJ$610,"Yes") | M15: =COUNTIFS('EL scheme register'!$A$7:$A$610,$A15,'EL scheme register'!$C$7:$C$610,"Unclear",'EL scheme register'!$AJ$7:$AJ$610,"Yes") | N15: =SUM(I15:M15) | O15: =COUNTIFS('EL scheme register'!$A$7:$A$610,$A15,'EL scheme register'!$AF$7:$AF$610,"Potentially relevant; evidence incomplete",'EL scheme register'!$AI$7:$AI$610,"Yes") | P15: =COUNTIFS('EL scheme register'!$A$7:$A$610,$A15,'EL scheme register'!$AF$7:$AF$610,"Outside strict definition") | Q15: =COUNTIF('EL exclusions & gaps'!$B$7:$B$5000,$A15) | R15: Not evidenced | S15: Not evidenced | T15: Strategic Marketing Consulting Project (BUSI70292) [Programme/course]; MSc Business Analytics & AI Consulting Project (capstone option) [Programme/course]; MSc Management Consulting Project [Programme/course]; Hounslow Heath Project (MSc Environmental Technology: Environmental Assessment and Management option) [Programme/course] | U15: Business/management: 3; Science: 1 | V15: Several distributed routes | W15: Imperial's strongest employer-linked group provision sits in the Business School and a few engineering/environment programmes, with no institution-wide scheme found. The Business School's MSc Group Consulting Projects (June-July 2026 call; 4-5 weeks; teams of 5-7 from seven MSc programmes) take real briefs from companies, which are free to participate; students bid for them and present recommendations to a panel including company representatives. These run as elective capstone options (e.g. Strategic Marketing Consulting Project BUSI70292, 10 ECTS; Business Analytics & AI; Management; Economics & Strategy; Climate Change, Management & Finance). The MBA equivalent (Perspectives on Practice) is individual. In science, the MSc Environmental Technology (EAM option) Hounslow Heath project is a group technical report for Hounslow Borough Council with team presentations to the client (2025-26 specification). In engineering, the EEE third-year MEng group project (industry-proposed, groups of 5-7, industrial and academic supervisors) and the Computing Year 3 Software Engineering Group Project (customers, many industry-proposed) are strong leads, but current-year delivery or share of externa | X15: Further departmental instances likely (e.g. Bioengineering, Materials, Chemical Engineering, Earth Science, Physics/Chemistry industry projects, Faculty of Medicine). Extracurricular employer-set challenges (Careers competitions such as Accuracy Business Cup, Siemens/Sony) and the Imperial College Consultancy Society not verified. Credit weightings, module codes and cohort sizes mostly not extracted (search summaries only; no verbatim page quotes for most). Current-year evidence needed for S5, S6, S7, S9, S10. UROP/internship routes were not examined (individual).
A16: RG10 | B16: King’s College London | C16: UK | D16: Russell Group | E16: UK – Russell Group | F16: 2027 | G16: 37 | H16: Complete | I16: =COUNTIFS('EL scheme register'!$A$7:$A$610,$A16,'EL scheme register'!$C$7:$C$610,"University-wide",'EL scheme register'!$AJ$7:$AJ$610,"Yes") | J16: =COUNTIFS('EL scheme register'!$A$7:$A$610,$A16,'EL scheme register'!$C$7:$C$610,"Cross-faculty",'EL scheme register'!$AJ$7:$AJ$610,"Yes") | K16: =COUNTIFS('EL scheme register'!$A$7:$A$610,$A16,'EL scheme register'!$C$7:$C$610,"Faculty/school",'EL scheme register'!$AJ$7:$AJ$610,"Yes") | L16: =COUNTIFS('EL scheme register'!$A$7:$A$610,$A16,'EL scheme register'!$C$7:$C$610,"Programme/course",'EL scheme register'!$AJ$7:$AJ$610,"Yes") | M16: =COUNTIFS('EL scheme register'!$A$7:$A$610,$A16,'EL scheme register'!$C$7:$C$610,"Unclear",'EL scheme register'!$AJ$7:$AJ$610,"Yes") | N16: =SUM(I16:M16) | O16: =COUNTIFS('EL scheme register'!$A$7:$A$610,$A16,'EL scheme register'!$AF$7:$AF$610,"Potentially relevant; evidence incomplete",'EL scheme register'!$AI$7:$AI$610,"Yes") | P16: =COUNTIFS('EL scheme register'!$A$7:$A$610,$A16,'EL scheme register'!$AF$7:$AF$610,"Outside strict definition") | Q16: =COUNTIF('EL exclusions & gaps'!$B$7:$B$5000,$A16) | R16: Not evidenced | S16: Not evidenced | T16: King's Business School Consultancy (Strategy consultancy support for London enterprises; originally Business Consultancy Scheme) [Faculty/school] | U16: Business/management: 1 | V16: Several distributed routes | W16: King's College London (partial review) has live-client project provision spread across the Business School, Informatics and central civic and careers units. Some routes are confirmed to involve group working; for others it is unverified. - Fully qualifying, current: The King's Business School Consultancy places teams of 3-4 final-year economics, business and management undergraduates with up to 15 local enterprises. Teams deliver a presentation and written recommendations, and a summer 2026 call is open. - Qualifying but undated: On the MSc Advanced Software Engineering, teams build software for external partners, including public-sector challenges with AWS mentors (Richmond and Wandsworth Councils). The Careers Insights Programme runs 2-week group virtual micro-internships on employer-proposed briefs for final-year undergraduates across all nine faculties. - Live clients, group working unclear: Informatics' Knowledge Exchange Projects (over 90 since 2022; partners set the brief, join supervision and receive the software; up to five students per brief; 2025/26 confirmed). PPM Consultancy (NHS trusts, Hackney, charities; Jan-Apr 2026). The MSc International Management Business Consu | X16: Science, AHSS and other searched lightly (1-2 queries each); further departmental instances likely. Group-working evidence missing for KEPs, PPM Consultancy, IM Business Consulting Project and the GHRM Benifex project. Dated current-year evidence missing for Insights, MSc ASE partner project and Civic Challenge. Whether Insights and CLA are open to all students or targeted at under-represented groups. KBS Consultancy timing inconsistency (summer 2026 vs w/c 30 November). Further departmental instances likely (e.g. KBS MSc capstones, SSPP charity projects, Policy Institute).
